WARNING: underlay of /etc/cvmfs/CMS_SITECONF/local required more than 50 (143) bind mounts
ERROR:syne_tune.tuner:Stopped as 1 failures were reached
ERROR:syne_tune.tuner:showing log of first failure
ERROR:syne_tune.tuner:sagemaker.config INFO - Not applying SDK defaults from location: /etc/xdg/sagemaker/config.yaml
sagemaker.config INFO - Not applying SDK defaults from location: /home/choij/.config/sagemaker/config.yaml

ERROR:syne_tune.tuner:Traceback (most recent call last):
  File "/data6/Users/choij/ChargedHiggsAnalysisV2/ParticleNet/./python/trainModelSimple.py", line 172, in <module>
    main()
  File "/data6/Users/choij/ChargedHiggsAnalysisV2/ParticleNet/./python/trainModelSimple.py", line 159, in main
    train(model, optimizer, scheduler, use_plateau_scheduler=(args.scheduler=="ReduceLROnPlateau"))
  File "/data6/Users/choij/ChargedHiggsAnalysisV2/ParticleNet/./python/trainModelSimple.py", line 86, in train
    out = model(data.x.to(args.device), data.edge_index.to(args.device), data.graphInput.to(args.device), data.batch.to(args.device))
          ^^^^^^^^^^^^^^^^^^^^^^^^^^^^^^^^^^^^^^^^^^^^^^^^^^^^^^^^^^^^^^^^^^^^^^^^^^^^^^^^^^^^^^^^^^^^^^^^^^^^^^^^^^^^^^^^^^^^^^^^^^^
  File "/opt/conda/envs/pyg/lib/python3.11/site-packages/torch/nn/modules/module.py", line 1532, in _wrapped_call_impl
    return self._call_impl(*args, **kwargs)
           ^^^^^^^^^^^^^^^^^^^^^^^^^^^^^^^^
  File "/opt/conda/envs/pyg/lib/python3.11/site-packages/torch/nn/modules/module.py", line 1541, in _call_impl
    return forward_call(*args, **kwargs)
           ^^^^^^^^^^^^^^^^^^^^^^^^^^^^^
  File "/data6/Users/choij/ChargedHiggsAnalysisV2/ParticleNet/python/Models.py", line 246, in forward
    conv2 = self.conv2(conv1, batch=batch)
            ^^^^^^^^^^^^^^^^^^^^^^^^^^^^^^
  File "/opt/conda/envs/pyg/lib/python3.11/site-packages/torch/nn/modules/module.py", line 1532, in _wrapped_call_impl
    return self._call_impl(*args, **kwargs)
           ^^^^^^^^^^^^^^^^^^^^^^^^^^^^^^^^
  File "/opt/conda/envs/pyg/lib/python3.11/site-packages/torch/nn/modules/module.py", line 1541, in _call_impl
    return forward_call(*args, **kwargs)
           ^^^^^^^^^^^^^^^^^^^^^^^^^^^^^
  File "/data6/Users/choij/ChargedHiggsAnalysisV2/ParticleNet/python/Models.py", line 141, in forward
    out = super().forward(x, edge_index, batch=batch)
          ^^^^^^^^^^^^^^^^^^^^^^^^^^^^^^^^^^^^^^^^^^^
  File "/data6/Users/choij/ChargedHiggsAnalysisV2/ParticleNet/python/Models.py", line 122, in forward
    return self.propagate(edge_index, x=x, batch=batch)
           ^^^^^^^^^^^^^^^^^^^^^^^^^^^^^^^^^^^^^^^^^^^^
  File "/tmp/Models_DynamicEdgeConv_propagate_6c0hbsix.py", line 178, in propagate
    out = self.message(
          ^^^^^^^^^^^^^
  File "/data6/Users/choij/ChargedHiggsAnalysisV2/ParticleNet/python/Models.py", line 126, in message
    return self.mlp(tmp)
           ^^^^^^^^^^^^^
  File "/opt/conda/envs/pyg/lib/python3.11/site-packages/torch/nn/modules/module.py", line 1532, in _wrapped_call_impl
    return self._call_impl(*args, **kwargs)
           ^^^^^^^^^^^^^^^^^^^^^^^^^^^^^^^^
  File "/opt/conda/envs/pyg/lib/python3.11/site-packages/torch/nn/modules/module.py", line 1541, in _call_impl
    return forward_call(*args, **kwargs)
           ^^^^^^^^^^^^^^^^^^^^^^^^^^^^^
  File "/opt/conda/envs/pyg/lib/python3.11/site-packages/torch/nn/modules/container.py", line 217, in forward
    input = module(input)
            ^^^^^^^^^^^^^
  File "/opt/conda/envs/pyg/lib/python3.11/site-packages/torch/nn/modules/module.py", line 1532, in _wrapped_call_impl
    return self._call_impl(*args, **kwargs)
           ^^^^^^^^^^^^^^^^^^^^^^^^^^^^^^^^
  File "/opt/conda/envs/pyg/lib/python3.11/site-packages/torch/nn/modules/module.py", line 1541, in _call_impl
    return forward_call(*args, **kwargs)
           ^^^^^^^^^^^^^^^^^^^^^^^^^^^^^
  File "/opt/conda/envs/pyg/lib/python3.11/site-packages/torch/nn/modules/linear.py", line 116, in forward
    return F.linear(input, self.weight, self.bias)
           ^^^^^^^^^^^^^^^^^^^^^^^^^^^^^^^^^^^^^^^
RuntimeError: mat1 and mat2 shapes cannot be multiplied (27040x64 and 68x34)

Traceback (most recent call last):
  File "/data6/Users/choij/ChargedHiggsAnalysisV2/ParticleNet/python/launchHPO.py", line 52, in <module>
    tuner.run()
  File "/root/syne-tune/syne_tune/tuner.py", line 370, in run
    self._handle_failure(done_trials_statuses=done_trials_statuses)
  File "/root/syne-tune/syne_tune/tuner.py", line 549, in _handle_failure
    raise ValueError(f"Trial - {trial_id} failed")
ValueError: Trial - 3 failed
